[2025-08-22 11:41:41,790: INFO: main: Data Ingestion stage started.]
[2025-08-22 11:41:41,791: INFO: common: yaml file: config/config.yaml loaded successfully]
[2025-08-22 11:41:41,793: INFO: common: yaml file: params.yaml loaded successfully]
[2025-08-22 11:41:41,794: INFO: common: yaml file: schema.yaml loaded successfully]
[2025-08-22 11:41:41,795: INFO: common: created directory at: artifacts]
[2025-08-22 11:41:41,795: INFO: common: created directory at: artifacts/data_ingestion]
[2025-08-22 11:41:43,008: INFO: data_ingestion: artifacts/data_ingestion/data.zip download with following info: 
Date: Fri, 22 Aug 2025 05:56:42 GMT
Content-Type: text/html; charset=utf-8
Vary: X-PJAX, X-PJAX-Container, Turbo-Visit, Turbo-Frame, X-Requested-With,Accept-Encoding, Accept, X-Requested-With
x-repository-download: git clone https://github.com/suzzane123/End-to-end-MLProject.git
x-raw-download: https://raw.githubusercontent.com/suzzane123/End-to-end-MLProject/main/winequality-data.zip
ETag: W/"bcff457a80ef86180bf8ff922f100f4f"
Cache-Control: max-age=0, private, must-revalidate
Strict-Transport-Security: max-age=31536000; includeSubdomains; preload
X-Frame-Options: deny
X-Content-Type-Options: nosniff
X-XSS-Protection: 0
Referrer-Policy: no-referrer-when-downgrade
Content-Security-Policy: default-src 'none'; base-uri 'self'; child-src github.githubassets.com github.com/assets-cdn/worker/ github.com/assets/ gist.github.com/assets-cdn/worker/; connect-src 'self' uploads.github.com www.githubstatus.com collector.github.com raw.githubusercontent.com api.github.com github-cloud.s3.amazonaws.com github-production-repository-file-5c1aeb.s3.amazonaws.com github-production-upload-manifest-file-7fdce7.s3.amazonaws.com github-production-user-asset-6210df.s3.amazonaws.com *.rel.tunnels.api.visualstudio.com wss://*.rel.tunnels.api.visualstudio.com objects-origin.githubusercontent.com copilot-proxy.githubusercontent.com proxy.individual.githubcopilot.com proxy.business.githubcopilot.com proxy.enterprise.githubcopilot.com *.actions.githubusercontent.com wss://*.actions.githubusercontent.com productionresultssa0.blob.core.windows.net/ productionresultssa1.blob.core.windows.net/ productionresultssa2.blob.core.windows.net/ productionresultssa3.blob.core.windows.net/ productionresultssa4.blob.core.windows.net/ productionresultssa5.blob.core.windows.net/ productionresultssa6.blob.core.windows.net/ productionresultssa7.blob.core.windows.net/ productionresultssa8.blob.core.windows.net/ productionresultssa9.blob.core.windows.net/ productionresultssa10.blob.core.windows.net/ productionresultssa11.blob.core.windows.net/ productionresultssa12.blob.core.windows.net/ productionresultssa13.blob.core.windows.net/ productionresultssa14.blob.core.windows.net/ productionresultssa15.blob.core.windows.net/ productionresultssa16.blob.core.windows.net/ productionresultssa17.blob.core.windows.net/ productionresultssa18.blob.core.windows.net/ productionresultssa19.blob.core.windows.net/ github-production-repository-image-32fea6.s3.amazonaws.com github-production-release-asset-2e65be.s3.amazonaws.com insights.github.com wss://alive.github.com wss://alive-staging.github.com api.githubcopilot.com api.individual.githubcopilot.com api.business.githubcopilot.com api.enterprise.githubcopilot.com; font-src github.githubassets.com; form-action 'self' github.com gist.github.com copilot-workspace.githubnext.com objects-origin.githubusercontent.com; frame-ancestors 'none'; frame-src viewscreen.githubusercontent.com notebooks.githubusercontent.com; img-src 'self' data: blob: github.githubassets.com media.githubusercontent.com camo.githubusercontent.com identicons.github.com avatars.githubusercontent.com private-avatars.githubusercontent.com github-cloud.s3.amazonaws.com objects.githubusercontent.com release-assets.githubusercontent.com secured-user-images.githubusercontent.com/ user-images.githubusercontent.com/ private-user-images.githubusercontent.com opengraph.githubassets.com copilotprodattachments.blob.core.windows.net/github-production-copilot-attachments/ github-production-user-asset-6210df.s3.amazonaws.com customer-stories-feed.github.com spotlights-feed.github.com objects-origin.githubusercontent.com *.githubusercontent.com; manifest-src 'self'; media-src github.com user-images.githubusercontent.com/ secured-user-images.githubusercontent.com/ private-user-images.githubusercontent.com github-production-user-asset-6210df.s3.amazonaws.com gist.github.com; script-src github.githubassets.com; style-src 'unsafe-inline' github.githubassets.com; upgrade-insecure-requests; worker-src github.githubassets.com github.com/assets-cdn/worker/ github.com/assets/ gist.github.com/assets-cdn/worker/
Server: github.com
Accept-Ranges: bytes
Set-Cookie: _gh_sess=nO0YvMY%2FEHBFR1qdrlCLjVkzaqQgCDh2Jb9EPNGj%2BfosKEiGuPd8l2VOgqyzodiu305NM4q1nvnwr4FowMih0Av0oYFYbnxDaE6mhfqrHZ6xitpyftQvusptpcN5Np6nhF3Hvi0lwtb2Un1A4VhAuNdDEaxxGKBxldSB2%2FK0khQrDUyjylcmFlzBie6hemFj%2B9FGcxXuCxYZIl%2B0iIfyi5qKYijKjcnpp5CpHEkPx2EP04oAzSC0tCvAR5SbS6423XzsQZpvKyznrHK%2FA8yfSw%3D%3D--rJERABFrODmpI%2F5V--mngXBHirQlp9grr4s%2BFsLA%3D%3D; Path=/; HttpOnly; Secure; SameSite=Lax
Set-Cookie: _octo=GH1.1.437028641.1755842202; Path=/; Domain=github.com; Expires=Sat, 22 Aug 2026 05:56:42 GMT; Secure; SameSite=Lax
Set-Cookie: logged_in=no; Path=/; Domain=github.com; Expires=Sat, 22 Aug 2026 05:56:42 GMT; HttpOnly; Secure; SameSite=Lax
X-GitHub-Request-Id: 3314:164596:106CC8:12D04B:68A8069A
connection: close
Transfer-Encoding: chunked

]
[2025-08-22 11:41:43,009: ERROR: stage_01_data_ingestion: Error occurred in Data Ingestion stage: File is not a zip file]
Traceback (most recent call last):
  File "/Users/sushantthapa/Desktop/End-to-end-MLProject/src/mlProject/pipeline/stage_01_data_ingestion.py", line 18, in main
    data_ingestion.extract_zip_file()
    ~~~~~~~~~~~~~~~~~~~~~~~~~~~~~~~^^
  File "/Users/sushantthapa/Desktop/End-to-end-MLProject/src/mlProject/components/data_ingestion.py", line 34, in extract_zip_file
    with zipfile.ZipFile(self.config.local_data_file, 'r') as zip_ref:
         ~~~~~~~~~~~~~~~^^^^^^^^^^^^^^^^^^^^^^^^^^^^^^^^^^
  File "/Users/sushantthapa/miniconda/envs/mlproj/lib/python3.13/zipfile/__init__.py", line 1385, in __init__
    self._RealGetContents()
    ~~~~~~~~~~~~~~~~~~~~~^^
  File "/Users/sushantthapa/miniconda/envs/mlproj/lib/python3.13/zipfile/__init__.py", line 1452, in _RealGetContents
    raise BadZipFile("File is not a zip file")
zipfile.BadZipFile: File is not a zip file
[2025-08-22 11:41:43,015: ERROR: main: Error in Data Ingestion stage: File is not a zip file]
Traceback (most recent call last):
  File "/Users/sushantthapa/Desktop/End-to-end-MLProject/main.py", line 9, in <module>
    obj.main()
    ~~~~~~~~^^
  File "/Users/sushantthapa/Desktop/End-to-end-MLProject/src/mlProject/pipeline/stage_01_data_ingestion.py", line 22, in main
    raise e
  File "/Users/sushantthapa/Desktop/End-to-end-MLProject/src/mlProject/pipeline/stage_01_data_ingestion.py", line 18, in main
    data_ingestion.extract_zip_file()
    ~~~~~~~~~~~~~~~~~~~~~~~~~~~~~~~^^
  File "/Users/sushantthapa/Desktop/End-to-end-MLProject/src/mlProject/components/data_ingestion.py", line 34, in extract_zip_file
    with zipfile.ZipFile(self.config.local_data_file, 'r') as zip_ref:
         ~~~~~~~~~~~~~~~^^^^^^^^^^^^^^^^^^^^^^^^^^^^^^^^^^
  File "/Users/sushantthapa/miniconda/envs/mlproj/lib/python3.13/zipfile/__init__.py", line 1385, in __init__
    self._RealGetContents()
    ~~~~~~~~~~~~~~~~~~~~~^^
  File "/Users/sushantthapa/miniconda/envs/mlproj/lib/python3.13/zipfile/__init__.py", line 1452, in _RealGetContents
    raise BadZipFile("File is not a zip file")
zipfile.BadZipFile: File is not a zip file
[2025-08-22 11:49:17,558: INFO: main: Data Ingestion stage started.]
[2025-08-22 11:49:17,559: INFO: common: yaml file: config/config.yaml loaded successfully]
[2025-08-22 11:49:17,560: INFO: common: yaml file: params.yaml loaded successfully]
[2025-08-22 11:49:17,561: INFO: common: yaml file: schema.yaml loaded successfully]
[2025-08-22 11:49:17,562: INFO: common: created directory at: artifacts]
[2025-08-22 11:49:17,562: INFO: common: created directory at: artifacts/data_ingestion]
[2025-08-22 11:49:17,563: ERROR: stage_01_data_ingestion: Error occurred in Data Ingestion stage: "'ConfigBox' object has no attribute 'local_data_file'"]
Traceback (most recent call last):
  File "box/box.py", line 594, in box.box.Box.__getitem__
KeyError: 'local_data_file'

The above exception was the direct cause of the following exception:

Traceback (most recent call last):
  File "box/box.py", line 633, in box.box.Box.__getattr__
  File "box/box.py", line 621, in box.box.Box.__getitem__
box.exceptions.BoxKeyError: "'local_data_file'"

During handling of the above exception, another exception occurred:

Traceback (most recent call last):
  File "box/box.py", line 635, in box.box.Box.__getattr__
AttributeError: 'ConfigBox' object has no attribute 'local_data_file'

The above exception was the direct cause of the following exception:

Traceback (most recent call last):
  File "box/config_box.py", line 29, in box.config_box.ConfigBox.__getattr__
  File "box/box.py", line 649, in box.box.Box.__getattr__
box.exceptions.BoxKeyError: "'ConfigBox' object has no attribute 'local_data_file'"

During handling of the above exception, another exception occurred:

Traceback (most recent call last):
  File "box/box.py", line 594, in box.box.Box.__getitem__
KeyError: 'local_data_file'

The above exception was the direct cause of the following exception:

Traceback (most recent call last):
  File "box/box.py", line 633, in box.box.Box.__getattr__
  File "box/box.py", line 621, in box.box.Box.__getitem__
box.exceptions.BoxKeyError: "'local_data_file'"

During handling of the above exception, another exception occurred:

Traceback (most recent call last):
  File "box/box.py", line 635, in box.box.Box.__getattr__
AttributeError: 'ConfigBox' object has no attribute 'local_data_file'

The above exception was the direct cause of the following exception:

Traceback (most recent call last):
  File "/Users/sushantthapa/Desktop/End-to-end-MLProject/src/mlProject/pipeline/stage_01_data_ingestion.py", line 15, in main
    data_ingestion_config = config.get_data_ingestion_config()
  File "/Users/sushantthapa/Desktop/End-to-end-MLProject/src/mlProject/config/configuration.py", line 23, in get_data_ingestion_config
    local_data_file=Path(config.local_data_file),
                         ^^^^^^^^^^^^^^^^^^^^^^
  File "box/config_box.py", line 31, in box.config_box.ConfigBox.__getattr__
  File "box/box.py", line 649, in box.box.Box.__getattr__
box.exceptions.BoxKeyError: "'ConfigBox' object has no attribute 'local_data_file'"
[2025-08-22 11:49:17,565: ERROR: main: Error in Data Ingestion stage: "'ConfigBox' object has no attribute 'local_data_file'"]
Traceback (most recent call last):
  File "box/box.py", line 594, in box.box.Box.__getitem__
KeyError: 'local_data_file'

The above exception was the direct cause of the following exception:

Traceback (most recent call last):
  File "box/box.py", line 633, in box.box.Box.__getattr__
  File "box/box.py", line 621, in box.box.Box.__getitem__
box.exceptions.BoxKeyError: "'local_data_file'"

During handling of the above exception, another exception occurred:

Traceback (most recent call last):
  File "box/box.py", line 635, in box.box.Box.__getattr__
AttributeError: 'ConfigBox' object has no attribute 'local_data_file'

The above exception was the direct cause of the following exception:

Traceback (most recent call last):
  File "box/config_box.py", line 29, in box.config_box.ConfigBox.__getattr__
  File "box/box.py", line 649, in box.box.Box.__getattr__
box.exceptions.BoxKeyError: "'ConfigBox' object has no attribute 'local_data_file'"

During handling of the above exception, another exception occurred:

Traceback (most recent call last):
  File "box/box.py", line 594, in box.box.Box.__getitem__
KeyError: 'local_data_file'

The above exception was the direct cause of the following exception:

Traceback (most recent call last):
  File "box/box.py", line 633, in box.box.Box.__getattr__
  File "box/box.py", line 621, in box.box.Box.__getitem__
box.exceptions.BoxKeyError: "'local_data_file'"

During handling of the above exception, another exception occurred:

Traceback (most recent call last):
  File "box/box.py", line 635, in box.box.Box.__getattr__
AttributeError: 'ConfigBox' object has no attribute 'local_data_file'

The above exception was the direct cause of the following exception:

Traceback (most recent call last):
  File "/Users/sushantthapa/Desktop/End-to-end-MLProject/main.py", line 9, in <module>
    obj.main()
    ~~~~~~~~^^
  File "/Users/sushantthapa/Desktop/End-to-end-MLProject/src/mlProject/pipeline/stage_01_data_ingestion.py", line 22, in main
    raise e
  File "/Users/sushantthapa/Desktop/End-to-end-MLProject/src/mlProject/pipeline/stage_01_data_ingestion.py", line 15, in main
    data_ingestion_config = config.get_data_ingestion_config()
  File "/Users/sushantthapa/Desktop/End-to-end-MLProject/src/mlProject/config/configuration.py", line 23, in get_data_ingestion_config
    local_data_file=Path(config.local_data_file),
                         ^^^^^^^^^^^^^^^^^^^^^^
  File "box/config_box.py", line 31, in box.config_box.ConfigBox.__getattr__
  File "box/box.py", line 649, in box.box.Box.__getattr__
box.exceptions.BoxKeyError: "'ConfigBox' object has no attribute 'local_data_file'"
